Workbook
Name TotalPlacecards: Convites!$E$4
Name TotalSlices: Bolo!$D$3
Name TotalThankyous: Convites!$H$3
Name TotalRSVPs: Convites!$E$3
Name TotalPrograms: Convites!$C$4
Name TotalBoutineers: Flores!$C$4
Name AdditionalPeople: 'Cabelo e maquiagem'!$C$4
Name Brides: 'Cabelo e maquiagem'!$C$3
Name TotalInvitations: Convites!$C$3
Name TotalBouquets: Flores!$C$3
Name TotalBudget: 'Estimativa de orçamento'!$C$5
Name HairHours: 'Cabelo e maquiagem'!$E$3
Name DinnerGuests: 'Bufê'!$D$3

Sheet Seções
C2: Planejamento do casamento | F2: Seções
C5: Facilite o planejamento do casamento usando este modelo para centralizar as informações. Faça o acompanhamento das tarefas, compare fornecedores, monitore o orçamento e planeje a cerimônia. Cada guia da página representa uma categoria. Preencha as guias na ordem que você quiser. Adicione, exclua ou personalize cada guia com base nas suas necessidades específicas. Compartilhe esta página com amigos e familiares para colaborar com eles. | F5: VISÃO GERAL | I5: ESTILO
G6: Tarefas | J6: Trajes
G7: Coordenação | J7: Cabelo e maquiagem
G8: Programação do dia do casamento | J8: Flores
F9: ORÇAMENTOS | I9: COMIDA
G10: Estimativa de orçamento | J10: Bolo de casamento
C11: =HYPERLINK("https://support.google.com/drive/answer/2494822?hl=pt-BR","Saiba como compartilhar formulários") -> Saiba como compartilhar formulários | G11: Orçamento detalhado | J11: Serviço de bufê
F12: CONVIDADOS | I12: FOTOGRAFIA
C13: OBSERVAÇÃO | G13: Lista de convidados | J13: Fotógrafo
C14: Algumas células contêm fórmulas. Tente não editá-las. Os valores serão recalculados automaticamente com base nos outros valores que você digitar. | G14: Convites | J14: Cinegrafista
G15: Mapa de assentos | I15: ENTRETENIMENTO
G16: Presentes | J16: Entretenimento
C17: Parabéns e divirta-se planejando seu grande dia! | F17: LOCAIS | J17: Música
G18: Local
G19: Hotel

Sheet Tarefas
B2: Lista de tarefas
B5: Tarefas | C5: Prazo | D5: Progresso | E5: Observações
B6: Encontrar seu parceiro ideal | C6: 36771 | D6: Concluída | E6: Altere a formatação dos itens com o status "Concluída" no menu "Formatar" > "Formatação condicional..." na Web.
B7: Primeiro digite a lista de convidados | C7: Hoje | D7: Em andamento | E7: Você pode adicionar ou remover opções de "Progresso" no menu "Dados" > "Validação..." na Web.
B8: Preencher as estimativas de planejamento e controle do orçamento | C8: 36774 | D8: Não iniciada
B9: Listar os endereços para o envio dos convites | C9: 36775 | D9: Não iniciada
B10: Criar um website do casamento para os convidados | C10: 36776 | D10: Não iniciada
B11: Entrevistar os fotógrafos | C11: 36777 | D11: Não iniciada
B12: Escolher o serviço de bufê | C12: Próximo mês | D12: Não iniciada
B13: Escolher o local da festa | D13: Não iniciada

Sheet Coordenação
B2: Coordenação | E2: Liste as funções que podem ser desempenhadas por amigos ou profissionais, como cerimonialista, juiz de paz ou mestre de cerimônia.
B5: Nome | C5: Função | D5: Telefone | E5: E-mail | F5: Website | G5: Custo | H5: Observações
B6: Primeiro Último | C6: Cerimonialista | D6: (55) 000-0000 | E6: email@email.com | F6: website.com | G6: 0

Sheet Programação
B2: Programação do dia do casamento
B5: Hora | D5: Item | E5: Observações
B6: 12h

Sheet Estimativa de orçamento
B2: Estimativa de orçamento
B3: Digite as estimativas de cada categoria abaixo. Você pode adicionar, remover ou personalizar as categorias não aplicáveis.
B4: Os totais serão calculados automaticamente. Os valores "Reais" são baseados na guia "Orçamento detalhado".
B5: Orçamento total: | C5: 25000
C7: Estimado | D7: Real | E7: % do orçamento
B8: Totais | C8: =sum(C9:C27) -> 25000 | D8: =sum(D9:D27) -> 300 | E8: =sum(E9:E27) -> 1
B9: Cerimônia | C9: 500 | D9: ='Orçamento detalhado'!D10 -> 300 | E9: =C9/TotalBudget -> 0.02
B10: Festa | C10: 750 | D10: ='Orçamento detalhado'!D17 -> 0 | E10: =C10/TotalBudget -> 0.03
B11: Materiais impressos | C11: 750 | D11: ='Orçamento detalhado'!D25 -> 0 | E11: =C11/TotalBudget -> 0.03
B12: Presentes/lembranças | C12: 750 | D12: ='Orçamento detalhado'!D33 -> 0 | E12: =C12/TotalBudget -> 0.03
B13: Local | C13: 2250 | D13: ='Orçamento detalhado'!D40 -> 0 | E13: =C13/TotalBudget -> 0.09
B14: Trajes | C14: 2250 | D14: ='Orçamento detalhado'!D47 -> 0 | E14: =C14/TotalBudget -> 0.09
B15: Alianças | C15: 500 | D15: ='Orçamento detalhado'!D53 -> 0 | E15: =C15/TotalBudget -> 0.02
B16: Cabelo e maquiagem | C16: 250 | D16: ='Orçamento detalhado'!D59 -> 0 | E16: =C16/TotalBudget -> 0.01
B17: Flores | C17: 2000 | D17: ='Orçamento detalhado'!D66 -> 0 | E17: =C17/TotalBudget -> 0.08
B18: Bolo | C18: 500 | D18: ='Orçamento detalhado'!D72 -> 0 | E18: =C18/TotalBudget -> 0.02
B19: Serviço de bufê e bebidas | C19: 8500 | D19: ='Orçamento detalhado'!D79 -> 0 | E19: =C19/TotalBudget -> 0.34
B20: Fotografia | C20: 3000 | D20: ='Orçamento detalhado'!D87 -> 0 | E20: =C20/TotalBudget -> 0.12
B21: Entretenimento | C21: 1750 | D21: ='Orçamento detalhado'!D94 -> 0 | E21: =C21/TotalBudget -> 0.07
B22: Diversos | C22: 1250 | D22: ='Orçamento detalhado'!D101 -> 0 | E22: =C22/TotalBudget -> 0.05
B23: Categoria personalizada 1 | E23: =C23/TotalBudget -> 0
B24: Categoria personalizada 2 | E24: =C24/TotalBudget -> 0
B25: Categoria personalizada 3 | E25: =C25/TotalBudget -> 0
B26: Categoria personalizada 4 | E26: =C26/TotalBudget -> 0

Sheet Orçamento detalhado
B2: Orçamento detalhado
B3: Depois de preencher a guia "Estimativa de orçamento", planeje e controle uma análise mais detalhada preenchendo os valores em "Estimado" e "Real". O "Orçamento previsto", o "Total estimado" e o "Total real" serão calculados automaticamente.
B5: ='Estimativa de orçamento'!$B$9 -> Cerimônia | C5: Estimado | D5: Real
B6: Decoração/acessórios | C6: 150 | D6: 300
B7: Locação | C7: 250 | D7: 0
B9: Orçamento previsto | C9: Total estimado | D9: Total real
B10: ='Estimativa de orçamento'!$C$9 -> 500 | C10: =sum(C6:C8) -> 400 | D10: =sum(D6:D8) -> 300
B12: ='Estimativa de orçamento'!$B$10 -> Festa | C12: Estimado | D12: Real
B13: Decoração | C13: 500 | D13: 0
B14: Estacionamento/transporte | C14: 250 | D14: 0
B16: Orçamento previsto | C16: Total estimado | D16: Total real
B17: ='Estimativa de orçamento'!$C$10 -> 750 | C17: =sum(C13:C15) -> 750 | D17: =sum(D13:D15) -> 0
B19: ='Estimativa de orçamento'!$B$11 -> Materiais impressos | C19: Estimado | D19: Real
B20: Pré-convites | C20: 100 | D20: 0
B21: Convites | C21: 625 | D21: 0
B22: Programas do casamento | C22: 100 | D22: 0
B24: Orçamento previsto | C24: Total estimado | D24: Total real
B25: ='Estimativa de orçamento'!$C$11 -> 750 | C25: =sum(C20:C23) -> 825 | D25: =sum(D20:D23) -> 0
B27: ='Estimativa de orçamento'!$B$12 -> Presentes/lembranças | C27: Estimado | D27: Real
B28: Presentes para padrinhos/madrinhas | C28: 250 | D28: 0
B29: Lembranças | C29: 375 | D29: 0
B30: Presentes para os pais | C30: 125 | D30: 0
B32: Orçamento previsto | C32: Total estimado | D32: Total real
B33: ='Estimativa de orçamento'!$C$12 -> 750 | C33: =sum(C28:C31) -> 750 | D33: =sum(D28:D31) -> 0
B35: ='Estimativa de orçamento'!$B$13 -> Local | C35: Estimado | D35: Real
B36: Locação | C36: 2000 | D36: 0
B37: Custos adicionais | C37: 250 | D37: 0
B39: Orçamento previsto | C39: Total estimado | D39: Total real
B40: ='Estimativa de orçamento'!$C$13 -> 2250 | C40: =sum(C36:C38) -> 2250 | D40: =sum(D36:D38) -> 0
B42: ='Estimativa de orçamento'!$B$14 -> Trajes | C42: Estimado | D42: Real
B43: Trajes de casamento | C43: 2000 | D43: 0
B44: Alterações | C44: 250 | D44: 0
B46: Orçamento previsto | C46: Total estimado | D46: Total real
B47: ='Estimativa de orçamento'!$C$14 -> 2250 | C47: =sum(C43:C45) -> 2250 | D47: =sum(D43:D45) -> 0
B49: ='Estimativa de orçamento'!$B$15 -> Alianças | C49: Estimado | D49: Real
B50: Alianças de casamento | C50: 500 | D50: 0
B52: Orçamento previsto | C52: Total estimado | D52: Total real
B53: ='Estimativa de orçamento'!$C$15 -> 500 | C53: =sum(C50:C51) -> 500 | D53: =sum(D50:D51) -> 0
B55: ='Estimativa de orçamento'!$B$16 -> Cabelo e maquiagem | C55: Estimado | D55: Real
B56: Cabelo/maquiagem | C56: 250 | D56: 0
...

Sheet Lista de convidados
B2: Lista de convidados | L2: Personalize sua lista de convidados adicionando linhas e colunas. Você pode renomear ou excluir as seções desnecessárias.
B4: INFORMAÇÕES DE CONTATO | G4: CONVITES | I4: CASAMENTO | L4: ENSAIO | N4: DETALHES
B5: Nomes | C5: Sobrenomes | D5: Endereço | E5: E-mail | F5: Convidado por... | G5: Pré-convite | H5: Convite | I5: Resposta | J5: Confirmados | K5: Crianças | L5: Número de convidados | M5: Confirmados | N5: Restrições alimentares | O5: Número da mesa | P5: Descrição do presente | Q5: Mensagem de agradecimento enviada? | R5: Observações
B6: Nome | C6: Sobrenome | D6: Endereço, 111, Nova York, NY 11201 | E6: email@email.com | G6: Enviado | H6: Enviado | I6: Talvez | J6: 2 | L6: 1 | N6: Vegetariano | O6: 1 | R6: Observações adicionais
B7: Nome | C7: Sobrenome

Sheet Convites
B2: Convites | K2: Altere o número total de convites, cartões e programas à esquerda. Em seguida, digite o custo por item na tabela abaixo. Os totais serão calculados automaticamente.
B3: Número de convites: | C3: 50 | D3: Número de cartões de RSVP: | E3: 50 | F3: Número de cartões de agradecimento: | H3: 50
B4: Número de programas: | C4: 50 | D4: Número de marcadores de lugar: | E4: 100
B7: Nome | C7: Telefone | D7: E-mail | E7: Website | F7: Convite | H7: Cartão de RSVP | J7: Mensagem de agradecimento | L7: Programa | N7: Marcador de lugar | P7: Custo total
B8: Papelaria | C8: (55) 000-0000 | D8: email@email.com | E8: website.com | F8: 0 | G8: =if(isblank(F8), "", concatenate("(",text(Convites!TotalInvitations*F8, "R$0")," total)")) -> (R$0 total) | H8: 0 | I8: =if(isblank(H8), "", concatenate("(",text(Convites!TotalRSVPs*H8, "R$0")," total)")) -> (R$0 total) | J8: 0 | K8: =if(isblank(J8), "", concatenate("(",text(Convites!TotalThankyous*J8, "R$0")," total)")) -> (R$0 total) | L8: 0 | M8: =if(isblank(L8), "", concatenate("(",text(Convites!TotalPrograms*L8, "R$0")," total)")) -> (R$0 total) | N8: 0 | O8: =if(isblank(N8), "", concatenate("(",text(Convites!TotalPlacecards*N8, "R$0")," total)")) -> (R$0 total) | P8: =sum((Convites!TotalInvitations*F8), (Convites!TotalRSVPs*H8), (Convites!TotalThankyous*J8), (Convites!TotalPrograms*L8), (Convites!TotalPlacecards*N8)) -> 0
G9: =if(isblank(F9), "", concatenate("(",text(Convites!TotalInvitations*F9, "$0")," total)")) | I9: =if(isblank(H9), "", concatenate("(",text(Convites!TotalRSVPs*H9, "$0")," total)")) | K9: =if(isblank(J9), "", concatenate("(",text(Convites!TotalThankyous*J9, "$0")," total)")) | M9: =if(isblank(L9), "", concatenate("(",text(Convites!TotalPrograms*L9, "$0")," total)")) | O9: =if(isblank(N9), "", concatenate("(",text(Convites!TotalPlacecards*N9, "$0")," total)")) | P9: =sum((Convites!TotalInvitations*F9), (Convites!TotalRSVPs*H9), (Convites!TotalThankyous*J9), (Convites!TotalPrograms*L9), (Convites!TotalPlacecards*N9)) -> 0
G10: =if(isblank(F10), "", concatenate("(",text(Convites!TotalInvitations*F10, "$0")," total)")) | I10: =if(isblank(H10), "", concatenate("(",text(Convites!TotalRSVPs*H10, "$0")," total)")) | K10: =if(isblank(J10), "", concatenate("(",text(Convites!TotalThankyous*J10, "$0")," total)")) | M10: =if(isblank(L10), "", concatenate("(",text(Convites!TotalPrograms*L10, "$0")," total)")) | O10: =if(isblank(N10), "", concatenate("(",text(Convites!TotalPlacecards*N10, "$0")," total)")) | P10: =sum((Convites!TotalInvitations*F10), (Convites!TotalRSVPs*H10), (Convites!TotalThankyous*J10), (Convites!TotalPrograms*L10), (Convites!TotalPlacecards*N10)) -> 0
G11: =if(isblank(F11), "", concatenate("(",text(Convites!TotalInvitations*F11, "$0")," total)")) | I11: =if(isblank(H11), "", concatenate("(",text(Convites!TotalRSVPs*H11, "$0")," total)")) | K11: =if(isblank(J11), "", concatenate("(",text(Convites!TotalThankyous*J11, "$0")," total)")) | M11: =if(isblank(L11), "", concatenate("(",text(Convites!TotalPrograms*L11, "$0")," total)")) | O11: =if(isblank(N11), "", concatenate("(",text(Convites!TotalPlacecards*N11, "$0")," total)")) | P11: =sum((Convites!TotalInvitations*F11), (Convites!TotalRSVPs*H11), (Convites!TotalThankyous*J11), (Convites!TotalPrograms*L11), (Convites!TotalPlacecards*N11)) -> 0
G12: =if(isblank(F12), "", concatenate("(",text(Convites!TotalInvitations*F12, "$0")," total)")) | I12: =if(isblank(H12), "", concatenate("(",text(Convites!TotalRSVPs*H12, "$0")," total)")) | K12: =if(isblank(J12), "", concatenate("(",text(Convites!TotalThankyous*J12, "$0")," total)")) | M12: =if(isblank(L12), "", concatenate("(",text(Convites!TotalPrograms*L12, "$0")," total)")) | O12: =if(isblank(N12), "", concatenate("(",text(Convites!TotalPlacecards*N12, "$0")," total)")) | P12: =sum((Convites!TotalInvitations*F12), (Convites!TotalRSVPs*H12), (Convites!TotalThankyous*J12), (Convites!TotalPrograms*L12), (Convites!TotalPlacecards*N12)) -> 0
G13: =if(isblank(F13), "", concatenate("(",text(Convites!TotalInvitations*F13, "$0")," total)")) | I13: =if(isblank(H13), "", concatenate("(",text(Convites!TotalRSVPs*H13, "$0")," total)")) | K13: =if(isblank(J13), "", concatenate("(",text(Convites!TotalThankyous*J13, "$0")," total)")) | M13: =if(isblank(L13), "", concatenate("(",text(Convites!TotalPrograms*L13, "$0")," total)")) | O13: =if(isblank(N13), "", concatenate("(",text(Convites!TotalPlacecards*N13, "$0")," total)")) | P13: =sum((Convites!TotalInvitations*F13), (Convites!TotalRSVPs*H13), (Convites!TotalThankyous*J13), (Convites!TotalPrograms*L13), (Convites!TotalPlacecards*N13)) -> 0
G14: =if(isblank(F14), "", concatenate("(",text(Convites!TotalInvitations*F14, "$0")," total)")) | I14: =if(isblank(H14), "", concatenate("(",text(Convites!TotalRSVPs*H14, "$0")," total)")) | K14: =if(isblank(J14), "", concatenate("(",text(Convites!TotalThankyous*J14, "$0")," total)")) | M14: =if(isblank(L14), "", concatenate("(",text(Convites!TotalPrograms*L14, "$0")," total)")) | O14: =if(isblank(N14), "", concatenate("(",text(Convites!TotalPlacecards*N14, "$0")," total)")) | P14: =sum((Convites!TotalInvitations*F14), (Convites!TotalRSVPs*H14), (Convites!TotalThankyous*J14), (Convites!TotalPrograms*L14), (Convites!TotalPlacecards*N14)) -> 0
G15: =if(isblank(F15), "", concatenate("(",text(Convites!TotalInvitations*F15, "$0")," total)")) | I15: =if(isblank(H15), "", concatenate("(",text(Convites!TotalRSVPs*H15, "$0")," total)")) | K15: =if(isblank(J15), "", concatenate("(",text(Convites!TotalThankyous*J15, "$0")," total)")) | M15: =if(isblank(L15), "", concatenate("(",text(Convites!TotalPrograms*L15, "$0")," total)")) | O15: =if(isblank(N15), "", concatenate("(",text(Convites!TotalPlacecards*N15, "$0")," total)")) | P15: =sum((Convites!TotalInvitations*F15), (Convites!TotalRSVPs*H15), (Convites!TotalThankyous*J15), (Convites!TotalPrograms*L15), (Convites!TotalPlacecards*N15)) -> 0
G16: =if(isblank(F16), "", concatenate("(",text(Convites!TotalInvitations*F16, "$0")," total)")) | I16: =if(isblank(H16), "", concatenate("(",text(Convites!TotalRSVPs*H16, "$0")," total)")) | K16: =if(isblank(J16), "", concatenate("(",text(Convites!TotalThankyous*J16, "$0")," total)")) | M16: =if(isblank(L16), "", concatenate("(",text(Convites!TotalPrograms*L16, "$0")," total)")) | O16: =if(isblank(N16), "", concatenate("(",text(Convites!TotalPlacecards*N16, "$0")," total)")) | P16: =sum((Convites!TotalInvitations*F16), (Convites!TotalRSVPs*H16), (Convites!TotalThankyous*J16), (Convites!TotalPrograms*L16), (Convites!TotalPlacecards*N16)) -> 0
G17: =if(isblank(F17), "", concatenate("(",text(Convites!TotalInvitations*F17, "$0")," total)")) | I17: =if(isblank(H17), "", concatenate("(",text(Convites!TotalRSVPs*H17, "$0")," total)")) | K17: =if(isblank(J17), "", concatenate("(",text(Convites!TotalThankyous*J17, "$0")," total)")) | M17: =if(isblank(L17), "", concatenate("(",text(Convites!TotalPrograms*L17, "$0")," total)")) | O17: =if(isblank(N17), "", concatenate("(",text(Convites!TotalPlacecards*N17, "$0")," total)")) | P17: =sum((Convites!TotalInvitations*F17), (Convites!TotalRSVPs*H17), (Convites!TotalThankyous*J17), (Convites!TotalPrograms*L17), (Convites!TotalPlacecards*N17)) -> 0
G18: =if(isblank(F18), "", concatenate("(",text(Convites!TotalInvitations*F18, "$0")," total)")) | I18: =if(isblank(H18), "", concatenate("(",text(Convites!TotalRSVPs*H18, "$0")," total)")) | K18: =if(isblank(J18), "", concatenate("(",text(Convites!TotalThankyous*J18, "$0")," total)")) | M18: =if(isblank(L18), "", concatenate("(",text(Convites!TotalPrograms*L18, "$0")," total)")) | O18: =if(isblank(N18), "", concatenate("(",text(Convites!TotalPlacecards*N18, "$0")," total)")) | P18: =sum((Convites!TotalInvitations*F18), (Convites!TotalRSVPs*H18), (Convites!TotalThankyous*J18), (Convites!TotalPrograms*L18), (Convites!TotalPlacecards*N18)) -> 0
G19: =if(isblank(F19), "", concatenate("(",text(Convites!TotalInvitations*F19, "$0")," total)")) | I19: =if(isblank(H19), "", concatenate("(",text(Convites!TotalRSVPs*H19, "$0")," total)")) | K19: =if(isblank(J19), "", concatenate("(",text(Convites!TotalThankyous*J19, "$0")," total)")) | M19: =if(isblank(L19), "", concatenate("(",text(Convites!TotalPrograms*L19, "$0")," total)")) | O19: =if(isblank(N19), "", concatenate("(",text(Convites!TotalPlacecards*N19, "$0")," total)")) | P19: =sum((Convites!TotalInvitations*F19), (Convites!TotalRSVPs*H19), (Convites!TotalThankyous*J19), (Convites!TotalPrograms*L19), (Convites!TotalPlacecards*N19)) -> 0

Sheet Presentes
B2: Presentes | F2: Liste as possíveis lembranças para os convidados e os presentes da festa de casamento.
B4: Nome | C4: Telefone | D4: E-mail | E4: Website | F4: Descrição do presente | G4: Número de presentes | H4: Custo (por presente) | I4: Total | K4: Observações
B6: LEMBRANÇAS | I6: =if(isblank(H6), "", G6*H6)
B7: Loja 1 | C7: (55) 000-0000 | D7: email@email.com | E7: website.com | F7: Descrição | G7: 0 | H7: 0 | I7: =G7*H7 -> 0
B8: Loja 2 | I8: =G8*H8 -> 0
B9: Loja 3 | I9: =G9*H9 -> 0
B10: Loja 4 | I10: =G10*H10 -> 0
B12: PRESENTES PARA PADRINHOS/MADRINHAS
B13: Loja A | C13: (55) 000-0000 | D13: email@email.com | E13: website.com | F13: Descrição | G13: 0 | H13: 0 | I13: =G13*H13 -> 0
B14: Loja B | I14: =G14*H14 -> 0
B15: Loja C | I15: =G15*H15 -> 0
B16: Loja D | I16: =G16*H16 -> 0

Sheet Mapa de assentos
B2: Mapa de assentos
B3: Depois que você preencher os nomes dos convidados, o número total de pessoas em cada mesa será exibido à direita na célula J3. | I3: Total de convidados: | J3: =sum(B16:J16, B29:J29) -> 1
B5: Mesa principal | C5: Mesa 1 | D5: Mesa 2 | E5: Mesa 3 | F5: Mesa 4 | G5: Mesa 5 | H5: Mesa 6 | I5: Mesa 7 | J5: Mesa 8
B6: Pessoa 1
B16: =counta(B6:B15) -> 1 | C16: =counta(C6:C15) -> 0 | D16: =counta(D6:D15) -> 0 | E16: =counta(E6:E15) -> 0 | F16: =counta(F6:F15) -> 0 | G16: =counta(G6:G15) -> 0 | H16: =counta(H6:H15) -> 0 | I16: =counta(I6:I15) -> 0 | J16: =counta(J6:J15) -> 0
B18: Mesa 9 | C18: Mesa 10 | D18: Mesa 11 | E18: Mesa 12 | F18: Mesa 13 | G18: Mesa 14 | H18: Mesa 15 | I18: Mesa 16 | J18: Mesa 17
B29: =counta(B19:B28) -> 0 | C29: =counta(C19:C28) -> 0 | D29: =counta(D19:D28) -> 0 | E29: =counta(E19:E28) -> 0 | F29: =counta(F19:F28) -> 0 | G29: =counta(G19:G28) -> 0 | H29: =counta(H19:H28) -> 0 | I29: =counta(I19:I28) -> 0 | J29: =counta(J19:J28) -> 0

Sheet Hotel
B2: Hotel | E2: Faça reservas com tarifas para grupos e reserve a suíte de núpcias se o casamento não for no hotel.
B5: Nome do hotel | C5: Nome do contato | D5: Telefone | E5: Website | F5: Diária do quarto para grupo | G5: Diária da suíte | H5: Número mínimo de quartos necessários | I5: Observações
B6: Hotel 1 | C6: Primeiro Último | D6: (55) 000-0000 | E6: website.com | F6: 0 | G6: 0 | H6: 0

Sheet Local
B2: Local | M2: Liste os possíveis locais do casamento.
B5: Local | C5: Nome do contato | D5: Telefone | E5: E-mail | F5: Website | G5: Endereço | H5: Capacidade | I5: Número de horas | J5: Custo do espaço | K5: Custo/pessoa | L5: Mínimo de comida/bebida | M5: Observações
B6: Nome do local | C6: Primeiro Último | D6: (55) 000-0000 | E6: email@email.com | F6: website.com | G6: Primeira Rua, 111, Nova York, NY 10011 | H6: 0 | I6: 0 | J6: 0 | K6: 0 | L6: 0

Sheet Cabelo e maquiagem
B2: Cabelo e maquiagem | H2: Compare diferentes maquiadores e cabeleireiros antes do grande dia. Como o preço da maquiagem da noiva costuma ser diferente, ele é listado separadamente.
B3: Noiva (cabelo/maquiagem): | C3: 1 | D3: Número de horas (cabelo): | E3: 3
B4: Pessoas adicionais: | C4: 5
G6: Maquiagem: noiva | K6: Maquiagem: outras pessoas
B7: Nome | C7: Telefone | D7: E-mail | E7: Website | F7: Preços | G7: Teste | H7: Dia do casamento | I7: Subtotal | K7: Dia do casamento | L7: Subtotal | N7: Custos adicionais | O7: Total | Q7: Observações
B8: Maquiador 1 | C8: (55) 000-0000 | D8: email@email.com | E8: website.com | F8: Por pessoa | G8: 0 | H8: 0 | I8: =if(isblank(H8), "",(H8+G8)*'Cabelo e maquiagem'!Brides) -> 0 | K8: 0 | L8: =if(isblank(K8), "", K8*('Cabelo e maquiagem'!AdditionalPeople)) -> 0 | N8: 0 | O8: =if(isblank(B8),"",sum(I8,L8,N8)) -> 0 | Q8: Observações
I9: =if(isblank(H9), "",(H9+G9)*'Cabelo e maquiagem'!Brides) | L9: =if(isblank(K9), "", K9*('Cabelo e maquiagem'!AdditionalPeople)) | O9: =if(isblank(B9),"",sum(I9,L9,N9))
I10: =if(isblank(H10), "",(H10+G10)*'Cabelo e maquiagem'!Brides) | L10: =if(isblank(K10), "", K10*('Cabelo e maquiagem'!AdditionalPeople)) | O10: =if(isblank(B10),"",sum(I10,L10,N10))
I11: =if(isblank(H11), "",(H11+G11)*'Cabelo e maquiagem'!Brides) | L11: =if(isblank(K11), "", K11*('Cabelo e maquiagem'!AdditionalPeople)) | O11: =if(isblank(B11),"",sum(I11,L11,N11))
I12: =if(isblank(H12), "",(H12+G12)*'Cabelo e maquiagem'!Brides) | L12: =if(isblank(K12), "", K12*('Cabelo e maquiagem'!AdditionalPeople)) | O12: =if(isblank(B12),"",sum(I12,L12,N12))
I13: =if(isblank(H13), "",(H13+G13)*'Cabelo e maquiagem'!Brides) | L13: =if(isblank(K13), "", K13*('Cabelo e maquiagem'!AdditionalPeople)) | O13: =if(isblank(B13),"",sum(I13,L13,N13))
I14: =if(isblank(H14), "",(H14+G14)*'Cabelo e maquiagem'!Brides) | L14: =if(isblank(K14), "", K14*('Cabelo e maquiagem'!AdditionalPeople)) | O14: =if(isblank(B14),"",sum(I14,L14,N14))
I15: =if(isblank(H15), "",(H15+G15)*'Cabelo e maquiagem'!Brides) | L15: =if(isblank(K15), "", K15*('Cabelo e maquiagem'!AdditionalPeople)) | O15: =if(isblank(B15),"",sum(I15,L15,N15))
I16: =if(isblank(H16), "",(H16+G16)*'Cabelo e maquiagem'!Brides) | L16: =if(isblank(K16), "", K16*('Cabelo e maquiagem'!AdditionalPeople)) | O16: =if(isblank(H16),"",sum(G16,H16,(K16*'Cabelo e maquiagem'!AdditionalPeople),N16))
G17: Cabelo: noiva | K17: Cabelo: outras pessoas
B18: Nome | C18: Telefone | D18: E-mail | E18: Website | F18: Preços | G18: Teste | H18: Dia do casamento | I18: Subtotal | K18: Dia do casamento | L18: Subtotal | N18: Custos adicionais | O18: Total | Q18: Observações
B19: Cabeleireiro 1 | C19: (55) 000-0000 | D19: email@email.com | E19: website.com | F19: Por hora | G19: 0 | H19: 0 | I19: =if(isblank(H19), "",(H19+G19)*'Cabelo e maquiagem'!Brides) -> 0 | K19: 0 | L19: =if(isblank(K19), "", if(F19 = "Per person", K19*'Cabelo e maquiagem'!AdditionalPeople, if(F19 = "Por hora", K19*'Cabelo e maquiagem'!HairHours, ""))) -> 0 | N19: 0 | O19: =if(isblank(B19),"",sum(I19,L19,N19)) -> 0 | Q19: Observações
I20: =if(isblank(H20), "",(H20+G20)*'Cabelo e maquiagem'!Brides) | L20: =if(isblank(K20), "", if(F20 = "Per person", K20*'Cabelo e maquiagem'!AdditionalPeople, if(F20 = "Por hora", K20*'Cabelo e maquiagem'!HairHours, ""))) | O20: =if(isblank(B20),"",sum(I20,L20,N20))
I21: =if(isblank(H21), "",(H21+G21)*'Cabelo e maquiagem'!Brides) | L21: =if(isblank(K21), "", if(F21 = "Per person", K21*'Cabelo e maquiagem'!AdditionalPeople, if(F21 = "Por hora", K21*'Cabelo e maquiagem'!HairHours, ""))) | O21: =if(isblank(B21),"",sum(I21,L21,N21))
I22: =if(isblank(H22), "",(H22+G22)*'Cabelo e maquiagem'!Brides) | L22: =if(isblank(K22), "", if(F22 = "Per person", K22*'Cabelo e maquiagem'!AdditionalPeople, if(F22 = "Por hora", K22*'Cabelo e maquiagem'!HairHours, ""))) | O22: =if(isblank(B22),"",sum(I22,L22,N22))
I23: =if(isblank(H23), "",(H23+G23)*'Cabelo e maquiagem'!Brides) | L23: =if(isblank(K23), "", if(F23 = "Per person", K23*'Cabelo e maquiagem'!AdditionalPeople, if(F23 = "Por hora", K23*'Cabelo e maquiagem'!HairHours, ""))) | O23: =if(isblank(B23),"",sum(I23,L23,N23))
I24: =if(isblank(H24), "",(H24+G24)*'Cabelo e maquiagem'!Brides) | L24: =if(isblank(K24), "", if(F24 = "Per person", K24*'Cabelo e maquiagem'!AdditionalPeople, if(F24 = "Por hora", K24*'Cabelo e maquiagem'!HairHours, ""))) | O24: =if(isblank(B24),"",sum(I24,L24,N24))

Sheet Flores
B2: Flores | I2: Lista de possíveis floristas e o custo dos principais itens.
B3: Número de buquês: | C3: 5
B4: Número de flores de lapela: | C4: 14
B7: Nome | C7: Telefone | D7: E-mail | E7: Website | F7: Buquê (noiva) | G7: Buquê (outros) | H7: Flor da lapela | I7: Outros | J7: Custo total | K7: Observações
B8: Florista 1 | C8: (55) 000-0000 | D8: email@email.com | E8: website.com | F8: 0 | G8: 0 | H8: 0 | I8: 0 | J8: =if(isblank(B8), "", sum(F8,(Flores!TotalBouquets*G8),(Flores!TotalBoutineers*H8),I8)) -> 0 | K8: Observações sobre os arranjos de flores
J9: =if(isblank(B9), "", sum(F9,(Flores!TotalBouquets*G9),(Flores!TotalBoutineers*H9),I9))
J10: =if(isblank(B10), "", sum(F10,(Flores!TotalBouquets*G10),(Flores!TotalBoutineers*H10),I10))
J11: =if(isblank(B11), "", sum(F11,(Flores!TotalBouquets*G11),(Flores!TotalBoutineers*H11),I11))
J12: =if(isblank(B12), "", sum(F12,(Flores!TotalBouquets*G12),(Flores!TotalBoutineers*H12),I12))
J13: =if(isblank(B13), "", sum(F13,(Flores!TotalBouquets*G13),(Flores!TotalBoutineers*H13),I13))
J14: =if(isblank(B14), "", sum(F14,(Flores!TotalBouquets*G14),(Flores!TotalBoutineers*H14),I14))
J15: =if(isblank(B15), "", sum(F15,(Flores!TotalBouquets*G15),(Flores!TotalBoutineers*H15),I15))
J16: =if(isblank(B16), "", sum(F16,(Flores!TotalBouquets*G16),(Flores!TotalBoutineers*H16),I16))
J17: =if(isblank(B17), "", sum(F17,(Flores!TotalBouquets*G17),(Flores!TotalBoutineers*H17),I17))
J18: =if(isblank(B18), "", sum(F18,(Flores!TotalBouquets*G18),(Flores!TotalBoutineers*H18),I18))
J19: =if(isblank(B19), "", sum(F19,(Flores!TotalBouquets*G19),(Flores!TotalBoutineers*H19),I19))

Sheet Trajes
B2: Traje do casamento
B5: Categoria | C5: Nome | D5: Telefone | E5: E-mail | F5: Website | G5: Precisa de alterações? | H5: Custo total | I5: Observações
B6: Vestidos de casamento | C6: Loja de vestidos de noivas 1 | D6: (55) 000-0000 | E6: email@email.com | F6: website.com | G6: Não | H6: 0 | I6: Inclui alterações

Sheet Bolo
B2: Bolo de casamento | G2: A maioria dos bolos é calculada por fatia. Pode haver encargos adicionais para a decoração e o transporte.
B3: Número de fatias (aproximado): | D3: 200
B6: Nome | C6: Telefone | D6: E-mail | E6: Website | F6: Custo (por fatia) | G6: Custo de transporte | H6: Custo total | I6: Observações
B7: Confeitaria | C7: (55) 000-0000 | D7: email@email.com | E7: website.com | F7: 0 | G7: 0 | H7: =(Bolo!TotalSlices*F7)+G7 -> 0
H8: =(Bolo!TotalSlices*F8)+G8 -> 0
H9: =(Bolo!TotalSlices*F9)+G9 -> 0
H10: =(Bolo!TotalSlices*F10)+G10 -> 0
H11: =(Bolo!TotalSlices*F11)+G11 -> 0
H12: =(Bolo!TotalSlices*F12)+G12 -> 0
H13: =(Bolo!TotalSlices*F13)+G13 -> 0
H14: =(Bolo!TotalSlices*F14)+G14 -> 0
H15: =(Bolo!TotalSlices*F15)+G15 -> 0
H16: =(Bolo!TotalSlices*F16)+G16 -> 0
H17: =(Bolo!TotalSlices*F17)+G17 -> 0
H18: =(Bolo!TotalSlices*F18)+G18 -> 0

Sheet Bufê
B2: Serviço de bufê | G2: Lista de possíveis serviços de bufê e descrição do estilo de comida.
B3: Número estimado de convidados: | D3: 80
B6: Serviço de bufê | C6: Nome do contato | D6: Telefone | E6: E-mail | F6: Website | G6: Custo/pessoa | H6: Custo total | I6: Observações
B7: Serviço de bufê 1 | C7: Primeiro Último | D7: (55) 000-0000 | E7: email@email.com | F7: website.com | G7: 0 | H7: ='Bufê'!DinnerGuests*G7 -> 0
H8: ='Bufê'!DinnerGuests*G8 -> 0
H9: ='Bufê'!DinnerGuests*G9 -> 0
H10: ='Bufê'!DinnerGuests*G10 -> 0
H11: ='Bufê'!DinnerGuests*G11 -> 0
H12: ='Bufê'!DinnerGuests*G12 -> 0
H13: ='Bufê'!DinnerGuests*G13 -> 0
H14: ='Bufê'!DinnerGuests*G14 -> 0
H15: ='Bufê'!DinnerGuests*G15 -> 0
H16: ='Bufê'!DinnerGuests*G16 -> 0
H17: ='Bufê'!DinnerGuests*G17 -> 0
H18: ='Bufê'!DinnerGuests*G18 -> 0

Sheet Fotógrafo
B2: Fotógrafo
B5: Nome | C5: Telefone | D5: E-mail | E5: Website | F5: Dia do casamento | G5: Fotos do noivado | H5: Álbum de fotos | I5: Custo total | J5: Observações
B6: Fotógrafo 1 | C6: (55) 000-0000 | D6: email@email.com | E6: website.com | F6: 0 | G6: 0 | H6: 0 | I6: =sum(F6:H6) -> 0
I7: =sum(F7:H7) -> 0
I8: =sum(F8:H8) -> 0
I9: =sum(F9:H9) -> 0
I10: =sum(F10:H10) -> 0
I11: =sum(F11:H11) -> 0
I12: =sum(F12:H12) -> 0
I13: =sum(F13:H13) -> 0
I14: =sum(F14:H14) -> 0
I15: =sum(F15:H15) -> 0
I16: =sum(F16:H16) -> 0
I17: =sum(F17:H17) -> 0

Sheet Cinegrafista
B2: Cinegrafista
B5: Nome | C5: Telefone | D5: E-mail | E5: Website | F5: Custo | G5: Observações
B6: Cinegrafista 1 | C6: (55) 000-0000 | D6: email@email.com | E6: website.com | F6: 0

Sheet Entretenimento
B2: Entretenimento | E2: Lista de possíveis DJs ou qualquer entretenimento ao vivo e o que está incluído no custo.
B5: Nome | C5: Telefone | D5: E-mail | E5: Website | F5: Custo estimado | G5: Horas | I5: Observações
B7: FESTA
B8: DJ | C8: (55) 000-0000 | D8: email@email.com | E8: website.com | F8: 0 | G8: 0
B12: CERIMÔNIA
B13: Quarteto de cordas | C13: (55) 000-0000 | D13: email@email.com | E13: website.com | F13: 0 | G13: 0

Sheet Música
B2: Música | D2: Lista de músicas a serem tocadas na cerimônia e na festa.
C5: Nome da música | D5: Artista | E5: Observações
B6: Cerimônia | C6: Música instrumental
